[2024-04-24 10:33:29,987] - 224  werkzeug - INFO- [31m[1mWARNING: This is a development server. Do not use it in a production deployment. Use a production WSGI server instead.[0m
 * Running on http://127.0.0.1:5000
[2024-04-24 10:33:29,987] - 224  werkzeug - INFO- [33mPress CTRL+C to quit[0m
[2024-04-24 10:33:36,351] - 1744  app - ERROR- Exception on /predict [POST]
Traceback (most recent call last):
  File "C:\Users\Pradyu\anaconda3\Lib\site-packages\flask\app.py", line 2529, in wsgi_app
    response = self.full_dispatch_request()
               ^^^^^^^^^^^^^^^^^^^^^^^^^^^^
  File "C:\Users\Pradyu\anaconda3\Lib\site-packages\flask\app.py", line 1825, in full_dispatch_request
    rv = self.handle_user_exception(e)
         ^^^^^^^^^^^^^^^^^^^^^^^^^^^^^
  File "C:\Users\Pradyu\anaconda3\Lib\site-packages\flask\app.py", line 1823, in full_dispatch_request
    rv = self.dispatch_request()
         ^^^^^^^^^^^^^^^^^^^^^^^
  File "C:\Users\Pradyu\anaconda3\Lib\site-packages\flask\app.py", line 1799, in dispatch_request
    return self.ensure_sync(self.view_functions[rule.endpoint])(**view_args)
           ^^^^^^^^^^^^^^^^^^^^^^^^^^^^^^^^^^^^^^^^^^^^^^^^^^^^^^^^^^^^^^^^^
  File "D:\Studies\Data Science\ProjectPro Projects\Customer Propensity Model\app.py", line 52, in predict_datapoint
    final_data=data.get_data_as_dataframe()
               ^^^^^^^^^^^^^^^^^^^^^^^^^^
AttributeError: 'CustomData' object has no attribute 'get_data_as_dataframe'
[2024-04-24 10:33:36,359] - 224  werkzeug - INFO- 127.0.0.1 - - [24/Apr/2024 10:33:36] "[35m[1mPOST /predict HTTP/1.1[0m" 500 -
