[2024-04-24 10:09:26,584] - 224  werkzeug - INFO- [31m[1mWARNING: This is a development server. Do not use it in a production deployment. Use a production WSGI server instead.[0m
 * Running on http://127.0.0.1:5000
[2024-04-24 10:09:26,584] - 224  werkzeug - INFO- [33mPress CTRL+C to quit[0m
[2024-04-24 10:09:26,828] - 224  werkzeug - INFO- 127.0.0.1 - - [24/Apr/2024 10:09:26] "GET /predict HTTP/1.1" 200 -
[2024-04-24 10:12:32,367] - 1744  app - ERROR- Exception on /predict [POST]
Traceback (most recent call last):
  File "C:\Users\Pradyu\anaconda3\Lib\site-packages\flask\app.py", line 2529, in wsgi_app
    response = self.full_dispatch_request()
               ^^^^^^^^^^^^^^^^^^^^^^^^^^^^
  File "C:\Users\Pradyu\anaconda3\Lib\site-packages\flask\app.py", line 1825, in full_dispatch_request
    rv = self.handle_user_exception(e)
         ^^^^^^^^^^^^^^^^^^^^^^^^^^^^^
  File "C:\Users\Pradyu\anaconda3\Lib\site-packages\flask\app.py", line 1823, in full_dispatch_request
    rv = self.dispatch_request()
         ^^^^^^^^^^^^^^^^^^^^^^^
  File "C:\Users\Pradyu\anaconda3\Lib\site-packages\flask\app.py", line 1799, in dispatch_request
    return self.ensure_sync(self.view_functions[rule.endpoint])(**view_args)
           ^^^^^^^^^^^^^^^^^^^^^^^^^^^^^^^^^^^^^^^^^^^^^^^^^^^^^^^^^^^^^^^^^
  File "D:\Studies\Data Science\ProjectPro Projects\Customer Propensity Model\app.py", line 29, in predict_datapoint
    data=CustomData(
         ^^^^^^^^^^^
TypeError: CustomData.__init__() got an unexpected keyword argument 'category'
[2024-04-24 10:12:32,367] - 224  werkzeug - INFO- 127.0.0.1 - - [24/Apr/2024 10:12:32] "[35m[1mPOST /predict HTTP/1.1[0m" 500 -
