[2024-05-24 12:29:06,248] - 224  werkzeug - INFO- [31m[1mWARNING: This is a development server. Do not use it in a production deployment. Use a production WSGI server instead.[0m
 * Running on http://127.0.0.1:5000
[2024-05-24 12:29:06,248] - 224  werkzeug - INFO- [33mPress CTRL+C to quit[0m
[2024-05-24 12:29:13,399] - 224  werkzeug - INFO- 127.0.0.1 - - [24/May/2024 12:29:13] "GET / HTTP/1.1" 200 -
[2024-05-24 12:29:13,656] - 224  werkzeug - INFO- 127.0.0.1 - - [24/May/2024 12:29:13] "[33mGET /favicon.ico HTTP/1.1[0m" 404 -
[2024-05-24 12:29:14,944] - 224  werkzeug - INFO- 127.0.0.1 - - [24/May/2024 12:29:14] "GET /predict HTTP/1.1" 200 -
[2024-05-24 12:29:38,637] - 109  root - INFO- Dataframe Gathered
[2024-05-24 12:29:38,639] - 110  root - INFO- The cols areIndex(['Category', 'SubCategory', 'days_active', 'R', 'F', 'M', 'Loyalty',
       'Avg Purchase Gap', 'add_to_cart_to_purchase_ratios',
       'add_to_wishlist_to_purchase_ratios',
       'click_wishlist_page_to_purchase_ratios', 'user_path',
       'cart_to_purchase_ratios_category',
       'cart_to_purchase_ratios_subcategory',
       'wishlist_to_purchase_ratios_category',
       'wishlist_to_purchase_ratios_subcategory',
       'click_wishlist_to_purchase_ratios_category',
       'click_wishlist_to_purchase_ratios_subcategory',
       'product_view_to_purchase_ratios_category',
       'product_view_to_purchase_ratios_subcategory'],
      dtype='object')
[2024-05-24 12:29:39,854] - 54  root - INFO- Exception Occured in load_object function utils
[2024-05-24 12:29:39,854] - 1744  app - ERROR- Exception on /predict [POST]
Traceback (most recent call last):
  File "D:\Studies\Data Science\Project Pro\Customer Propensity Model\src\utils\utils.py", line 52, in load_object
    return pickle.load(file_obj)
           ^^^^^^^^^^^^^^^^^^^^^
ModuleNotFoundError: No module named 'category_encoders'

During handling of the above exception, another exception occurred:

Traceback (most recent call last):
  File "D:\Studies\Data Science\Project Pro\Customer Propensity Model\src\pipeline\prediction_pipeline.py", line 19, in predict
    preprocessor = load_object(preprocessor_path)
                   ^^^^^^^^^^^^^^^^^^^^^^^^^^^^^^
  File "D:\Studies\Data Science\Project Pro\Customer Propensity Model\src\utils\utils.py", line 55, in load_object
    raise CustomException(e,sys)
src.exception.exception.CustomException: Error occured in the python script [ D:\Studies\Data Science\Project Pro\Customer Propensity Model\src\utils\utils.py ] at the line 52 Error message: No module named 'category_encoders'

During handling of the above exception, another exception occurred:

Traceback (most recent call last):
  File "C:\Users\prady\anaconda3\Lib\site-packages\flask\app.py", line 2529, in wsgi_app
    response = self.full_dispatch_request()
               ^^^^^^^^^^^^^^^^^^^^^^^^^^^^
  File "C:\Users\prady\anaconda3\Lib\site-packages\flask\app.py", line 1825, in full_dispatch_request
    rv = self.handle_user_exception(e)
         ^^^^^^^^^^^^^^^^^^^^^^^^^^^^^
  File "C:\Users\prady\anaconda3\Lib\site-packages\flask\app.py", line 1823, in full_dispatch_request
    rv = self.dispatch_request()
         ^^^^^^^^^^^^^^^^^^^^^^^
  File "C:\Users\prady\anaconda3\Lib\site-packages\flask\app.py", line 1799, in dispatch_request
    return self.ensure_sync(self.view_functions[rule.endpoint])(**view_args)
           ^^^^^^^^^^^^^^^^^^^^^^^^^^^^^^^^^^^^^^^^^^^^^^^^^^^^^^^^^^^^^^^^^
  File "D:\Studies\Data Science\Project Pro\Customer Propensity Model\app.py", line 62, in predict_datapoint
    pred=predict_pipeline.predict(final_data)
         ^^^^^^^^^^^^^^^^^^^^^^^^^^^^^^^^^^^^
  File "D:\Studies\Data Science\Project Pro\Customer Propensity Model\src\pipeline\prediction_pipeline.py", line 34, in predict
    raise CustomException(e,sys)
src.exception.exception.CustomException: Error occured in the python script [ D:\Studies\Data Science\Project Pro\Customer Propensity Model\src\pipeline\prediction_pipeline.py ] at the line 19 Error message: Error occured in the python script [ D:\Studies\Data Science\Project Pro\Customer Propensity Model\src\utils\utils.py ] at the line 52 Error message: No module named 'category_encoders'
[2024-05-24 12:29:39,857] - 224  werkzeug - INFO- 127.0.0.1 - - [24/May/2024 12:29:39] "[35m[1mPOST /predict HTTP/1.1[0m" 500 -
